2014-06-03 00:45:28,582 - Skype4Py.skype.Skype - INFO - object created
2014-06-03 00:45:28,582 - Skype4Py.api.windows.SkypeAPI - INFO - opened
2014-06-03 00:45:28,594 - Skype4Py.api.windows.SkypeAPI - INFO - thread started
2014-06-03 00:45:28,645 - Skype4Py.api.windows.SkypeAPI - INFO - attachment: 1
2014-06-03 00:45:28,660 - Skype4Py.api.windows.SkypeAPI - INFO - attachment: 0
2014-06-03 00:45:31,805 - Skype4Py.utils.EventHandlingBase - INFO - set default MessageStatus: <bound method MessageHandler.handle of <father.father_app.MessageHandler object at 0x03484F10>>
2014-06-03 00:45:31,806 - Father - INFO - Connected to skype, chat: #alex_ieshin/$father.no_more;c5e582de8bbb5d21 at <father.chat.Chat object at 0x03484EF0>
2014-06-03 00:45:38,453 - MessageHandler - INFO - Event processing started for message 3197449
2014-06-03 00:45:38,454 - root - ERROR - Got exception
Traceback (most recent call last):
  File "C:/svnwork/local/trunk/python/Father\father\father_app.py", line 39, in handle
    answer = self._plugin_mgr.run(chat_message.text, chat_message.from_display_name, self._config)
  File "C:/svnwork/local/trunk/python/Father\father\plugin_manager.py", line 62, in run
    and re.match(plugin.message_pattern, message, re.IGNORECASE):
  File "C:\Python276_86\lib\re.py", line 137, in match
    return _compile(pattern, flags).match(string)
  File "C:\Python276_86\lib\re.py", line 242, in _compile
    raise error, v # invalid expression
error: unexpected end of pattern
2014-06-03 00:45:38,456 - MessageHandler - INFO - Event processing finished for message 3197449
2014-06-03 00:46:11,145 - Skype4Py.skype.Skype - INFO - object created
2014-06-03 00:46:11,147 - Skype4Py.api.windows.SkypeAPI - INFO - opened
2014-06-03 00:46:11,157 - Skype4Py.api.windows.SkypeAPI - INFO - thread started
2014-06-03 00:46:11,204 - Skype4Py.api.windows.SkypeAPI - INFO - attachment: 1
2014-06-03 00:46:11,219 - Skype4Py.api.windows.SkypeAPI - INFO - attachment: 0
2014-06-03 00:46:13,529 - Skype4Py.utils.EventHandlingBase - INFO - set default MessageStatus: <bound method MessageHandler.handle of <father.father_app.MessageHandler object at 0x0348EF10>>
2014-06-03 00:46:13,529 - Father - INFO - Connected to skype, chat: #alex_ieshin/$father.no_more;c5e582de8bbb5d21 at <father.chat.Chat object at 0x0348EEF0>
2014-06-03 00:46:21,084 - MessageHandler - INFO - Event processing started for message 3197481
2014-06-03 00:46:21,086 - PluginManager - INFO - Run the plugin: <class 'father.plugins.random_plugin.RandomAnswerPlugin'>, user: alex_ieshin
2014-06-03 00:46:22,427 - root - ERROR - Got exception
Traceback (most recent call last):
  File "C:/svnwork/local/trunk/python/Father\father\father_app.py", line 39, in handle
    answer = self._plugin_mgr.run(chat_message.text, chat_message.from_display_name, self._config)
  File "C:/svnwork/local/trunk/python/Father\father\plugin_manager.py", line 65, in run
    PluginContext.get(config, plugin))
TypeError: get() takes exactly 3 arguments (2 given)
2014-06-03 00:46:22,428 - MessageHandler - INFO - Event processing finished for message 3197481
2014-06-03 00:47:06,408 - Skype4Py.skype.Skype - INFO - object created
2014-06-03 00:47:06,410 - Skype4Py.api.windows.SkypeAPI - INFO - opened
2014-06-03 00:47:06,421 - Skype4Py.api.windows.SkypeAPI - INFO - thread started
2014-06-03 00:47:06,456 - Skype4Py.api.windows.SkypeAPI - INFO - attachment: 1
2014-06-03 00:47:06,467 - Skype4Py.api.windows.SkypeAPI - INFO - attachment: 0
2014-06-03 00:47:11,558 - Skype4Py.utils.EventHandlingBase - INFO - set default MessageStatus: <bound method MessageHandler.handle of <father.father_app.MessageHandler object at 0x034FADB0>>
2014-06-03 00:47:11,559 - Father - INFO - Connected to skype, chat: #alex_ieshin/$father.no_more;c5e582de8bbb5d21 at <father.chat.Chat object at 0x02711ED0>
2014-06-03 00:47:18,789 - MessageHandler - INFO - Event processing started for message 3197513
2014-06-03 00:47:18,793 - PluginManager - INFO - Run the plugin: <class 'father.plugins.random_plugin.RandomAnswerPlugin'>, user: alex_ieshin
2014-06-03 00:47:20,441 - root - ERROR - Got exception
Traceback (most recent call last):
  File "C:/svnwork/local/trunk/python/Father\father\father_app.py", line 39, in handle
    answer = self._plugin_mgr.run(chat_message.text, chat_message.from_display_name, self._config)
  File "C:/svnwork/local/trunk/python/Father\father\plugin_manager.py", line 65, in run
    PluginContext.get(config, plugin))
  File "C:/svnwork/local/trunk/python/Father\father\plugin_manager.py", line 78, in get
    return config[plugin_name]
KeyError: <class 'father.plugins.random_plugin.RandomAnswerPlugin'>
2014-06-03 00:47:20,443 - MessageHandler - INFO - Event processing finished for message 3197513
2014-06-03 00:47:52,009 - Skype4Py.skype.Skype - INFO - object created
2014-06-03 00:47:52,010 - Skype4Py.api.windows.SkypeAPI - INFO - opened
2014-06-03 00:47:52,020 - Skype4Py.api.windows.SkypeAPI - INFO - thread started
2014-06-03 00:47:52,072 - Skype4Py.api.windows.SkypeAPI - INFO - attachment: 1
2014-06-03 00:47:52,084 - Skype4Py.api.windows.SkypeAPI - INFO - attachment: 0
2014-06-03 00:47:56,594 - Skype4Py.utils.EventHandlingBase - INFO - set default MessageStatus: <bound method MessageHandler.handle of <father.father_app.MessageHandler object at 0x034B4F90>>
2014-06-03 00:47:56,594 - Father - INFO - Connected to skype, chat: #alex_ieshin/$father.no_more;c5e582de8bbb5d21 at <father.chat.Chat object at 0x026D9050>
2014-06-03 00:48:01,737 - MessageHandler - INFO - Event processing started for message 3197545
2014-06-03 00:48:01,740 - PluginManager - INFO - Run the plugin: <class 'father.plugins.random_plugin.RandomAnswerPlugin'>, user: alex_ieshin
2014-06-03 00:49:58,930 - Skype4Py.skype.Skype - INFO - object created
2014-06-03 00:49:58,930 - Skype4Py.api.windows.SkypeAPI - INFO - opened
2014-06-03 00:49:58,940 - Skype4Py.api.windows.SkypeAPI - INFO - thread started
2014-06-03 00:49:58,992 - Skype4Py.api.windows.SkypeAPI - INFO - attachment: 1
2014-06-03 00:49:59,555 - Skype4Py.api.windows.SkypeAPI - INFO - attachment: 0
2014-06-03 00:50:01,538 - Skype4Py.utils.EventHandlingBase - INFO - set default MessageStatus: <bound method MessageHandler.handle of <father.father_app.MessageHandler object at 0x03474ED0>>
2014-06-03 00:50:01,539 - Father - INFO - Connected to skype, chat: #alex_ieshin/$father.no_more;c5e582de8bbb5d21 at <father.chat.Chat object at 0x03474EB0>
2014-06-03 00:50:06,845 - MessageHandler - INFO - Event processing started for message 3197577
2014-06-03 00:50:06,846 - PluginManager - INFO - Run the plugin: <class 'father.plugins.random_plugin.RandomAnswerPlugin'>, user: alex_ieshin
2014-06-03 00:50:56,888 - root - ERROR - Got exception
Traceback (most recent call last):
  File "C:/svnwork/local/trunk/python/Father\father\father_app.py", line 39, in handle
    answer = self._plugin_mgr.run(chat_message.text, chat_message.from_display_name, self._config)
  File "C:/svnwork/local/trunk/python/Father\father\plugin_manager.py", line 65, in run
    PluginContext.get(config, plugin.__name__))
  File "C:/svnwork/local/trunk/python/Father\father\plugin_manager.py", line 78, in get
    return config[plugin_name]
KeyError: 'RandomAnswerPlugin'
2014-06-03 00:50:56,890 - MessageHandler - INFO - Event processing finished for message 3197577
2014-06-03 00:52:59,641 - Skype4Py.skype.Skype - INFO - object created
2014-06-03 00:52:59,642 - Skype4Py.api.windows.SkypeAPI - INFO - opened
2014-06-03 00:52:59,653 - Skype4Py.api.windows.SkypeAPI - INFO - thread started
2014-06-03 00:52:59,701 - Skype4Py.api.windows.SkypeAPI - INFO - attachment: 1
2014-06-03 00:52:59,713 - Skype4Py.api.windows.SkypeAPI - INFO - attachment: 0
2014-06-03 00:53:02,811 - Skype4Py.utils.EventHandlingBase - INFO - set default MessageStatus: <bound method MessageHandler.handle of <father.father_app.MessageHandler object at 0x03486510>>
2014-06-03 00:53:02,812 - Father - INFO - Connected to skype, chat: #alex_ieshin/$father.no_more;c5e582de8bbb5d21 at <father.chat.Chat object at 0x03486470>
2014-06-03 00:53:09,677 - MessageHandler - INFO - Event processing started for message 3197609
2014-06-03 00:53:09,680 - PluginManager - INFO - Run the plugin: <class 'father.plugins.random_plugin.RandomAnswerPlugin'>, user: alex_ieshin
2014-06-03 00:53:09,680 - root - ERROR - Got exception
Traceback (most recent call last):
  File "C:/svnwork/local/trunk/python/Father\father\father_app.py", line 39, in handle
    answer = self._plugin_mgr.run(chat_message.text, chat_message.from_display_name, self._config)
  File "C:/svnwork/local/trunk/python/Father\father\plugin_manager.py", line 66, in run
    PluginContext.get(config, plugin))
  File "C:/svnwork/local/trunk/python/Father\father\plugins\random_plugin.py", line 13, in execute
    mp.parse()
  File "C:/svnwork/local/trunk/python/Father\father\plugins\libs\messages.py", line 30, in parse
    [CommonConstants.WISDOM_TAG]]
AttributeError: class CommonConstants has no attribute 'WISDOM_TAG'
2014-06-03 00:53:09,681 - MessageHandler - INFO - Event processing finished for message 3197609
2014-06-03 00:53:56,707 - Skype4Py.skype.Skype - INFO - object created
2014-06-03 00:53:56,709 - Skype4Py.api.windows.SkypeAPI - INFO - opened
2014-06-03 00:53:56,719 - Skype4Py.api.windows.SkypeAPI - INFO - thread started
2014-06-03 00:53:56,769 - Skype4Py.api.windows.SkypeAPI - INFO - attachment: 1
2014-06-03 00:53:56,782 - Skype4Py.api.windows.SkypeAPI - INFO - attachment: 0
2014-06-03 00:53:58,819 - Skype4Py.utils.EventHandlingBase - INFO - set default MessageStatus: <bound method MessageHandler.handle of <father.father_app.MessageHandler object at 0x0347B490>>
2014-06-03 00:53:58,821 - Father - INFO - Connected to skype, chat: #alex_ieshin/$father.no_more;c5e582de8bbb5d21 at <father.chat.Chat object at 0x0347B4B0>
2014-06-03 00:54:16,826 - MessageHandler - INFO - Event processing started for message 3197673
2014-06-03 00:54:16,829 - MessageHandler - INFO - Event processing finished for message 3197673
2014-06-03 00:54:35,447 - MessageHandler - INFO - Event processing started for message 3197705
2014-06-03 00:54:35,447 - PluginManager - INFO - Run the plugin: <class 'father.plugins.random_plugin.RandomAnswerPlugin'>, user: alex_ieshin
2014-06-03 00:54:36,275 - MessageHandler - INFO - Event processing finished for message 3197705
